Traceback (most recent call last):
  File "/home/runner/work/corneto/corneto/.venv/lib/python3.11/site-packages/jupyter_core/utils/__init__.py", line 154, in wrapped
    asyncio.get_running_loop()
RuntimeError: no running event loop

During handling of the above exception, another exception occurred:

Traceback (most recent call last):
  File "/home/runner/work/corneto/corneto/.venv/lib/python3.11/site-packages/jupyter_cache/executors/utils.py", line 58, in single_nb_execution
    executenb(
  File "/home/runner/work/corneto/corneto/.venv/lib/python3.11/site-packages/nbclient/client.py", line 1319, in execute
    return NotebookClient(nb=nb, resources=resources, km=km, **kwargs).execute()
           ^^^^^^^^^^^^^^^^^^^^^^^^^^^^^^^^^^^^^^^^^^^^^^^^^^^^^^^^^^^^^^^^^^^^^
  File "/home/runner/work/corneto/corneto/.venv/lib/python3.11/site-packages/jupyter_core/utils/__init__.py", line 158, in wrapped
    return loop.run_until_complete(inner)
           ^^^^^^^^^^^^^^^^^^^^^^^^^^^^^^
  File "/opt/hostedtoolcache/Python/3.11.13/x64/lib/python3.11/asyncio/base_events.py", line 654, in run_until_complete
    return future.result()
           ^^^^^^^^^^^^^^^
  File "/home/runner/work/corneto/corneto/.venv/lib/python3.11/site-packages/nbclient/client.py", line 709, in async_execute
    await self.async_execute_cell(
  File "/home/runner/work/corneto/corneto/.venv/lib/python3.11/site-packages/nbclient/client.py", line 1062, in async_execute_cell
    await self._check_raise_for_error(cell, cell_index, exec_reply)
  File "/home/runner/work/corneto/corneto/.venv/lib/python3.11/site-packages/nbclient/client.py", line 918, in _check_raise_for_error
    raise CellExecutionError.from_cell_and_msg(cell, exec_reply_content)
nbclient.exceptions.CellExecutionError: An error occurred while executing the following cell:
------------------
from corneto.data._ds import Dataset

raw_data = {
    "s1": {
        "rec1": {"value": 1, "type": "input"},
        "rec2": {"value": -1, "type": "input"},
        "tf1": {"value": 1, "type": "output"},
    },
    "s2": {
        "rec1": {"value": -1, "type": "input"},
        "tf1": {"value": -1, "type": "output"},
        "tf2": {"value": 1, "type": "output"},
    },
}
ds = Dataset.from_dict(raw_data)
ds
------------------


[0;31m---------------------------------------------------------------------------[0m
[0;31mModuleNotFoundError[0m                       Traceback (most recent call last)
Cell [0;32mIn[2], line 1[0m
[0;32m----> 1[0m [38;5;28;01mfrom[39;00m[38;5;250m [39m[38;5;21;01mcorneto[39;00m[38;5;21;01m.[39;00m[38;5;21;01mdata[39;00m[38;5;21;01m.[39;00m[38;5;21;01m_ds[39;00m[38;5;250m [39m[38;5;28;01mimport[39;00m Dataset
[1;32m      3[0m raw_data [38;5;241m=[39m {
[1;32m      4[0m     [38;5;124m"[39m[38;5;124ms1[39m[38;5;124m"[39m: {
[1;32m      5[0m         [38;5;124m"[39m[38;5;124mrec1[39m[38;5;124m"[39m: {[38;5;124m"[39m[38;5;124mvalue[39m[38;5;124m"[39m: [38;5;241m1[39m, [38;5;124m"[39m[38;5;124mtype[39m[38;5;124m"[39m: [38;5;124m"[39m[38;5;124minput[39m[38;5;124m"[39m},
[0;32m   (...)[0m
[1;32m     13[0m     },
[1;32m     14[0m }
[1;32m     15[0m ds [38;5;241m=[39m Dataset[38;5;241m.[39mfrom_dict(raw_data)

[0;31mModuleNotFoundError[0m: No module named 'corneto.data._ds'

