Traceback (most recent call last):
  File "/home/runner/.cache/pypoetry/virtualenvs/corneto-lU1q7eKj-py3.11/lib/python3.11/site-packages/jupyter_cache/executors/utils.py", line 58, in single_nb_execution
    executenb(
  File "/home/runner/.cache/pypoetry/virtualenvs/corneto-lU1q7eKj-py3.11/lib/python3.11/site-packages/nbclient/client.py", line 1319, in execute
    return NotebookClient(nb=nb, resources=resources, km=km, **kwargs).execute()
           ^^^^^^^^^^^^^^^^^^^^^^^^^^^^^^^^^^^^^^^^^^^^^^^^^^^^^^^^^^^^^^^^^^^^^
  File "/home/runner/.cache/pypoetry/virtualenvs/corneto-lU1q7eKj-py3.11/lib/python3.11/site-packages/jupyter_core/utils/__init__.py", line 165, in wrapped
    return loop.run_until_complete(inner)
           ^^^^^^^^^^^^^^^^^^^^^^^^^^^^^^
  File "/opt/hostedtoolcache/Python/3.11.12/x64/lib/python3.11/asyncio/base_events.py", line 654, in run_until_complete
    return future.result()
           ^^^^^^^^^^^^^^^
  File "/home/runner/.cache/pypoetry/virtualenvs/corneto-lU1q7eKj-py3.11/lib/python3.11/site-packages/nbclient/client.py", line 709, in async_execute
    await self.async_execute_cell(
  File "/home/runner/.cache/pypoetry/virtualenvs/corneto-lU1q7eKj-py3.11/lib/python3.11/site-packages/nbclient/client.py", line 1062, in async_execute_cell
    await self._check_raise_for_error(cell, cell_index, exec_reply)
  File "/home/runner/.cache/pypoetry/virtualenvs/corneto-lU1q7eKj-py3.11/lib/python3.11/site-packages/nbclient/client.py", line 918, in _check_raise_for_error
    raise CellExecutionError.from_cell_and_msg(cell, exec_reply_content)
nbclient.exceptions.CellExecutionError: An error occurred while executing the following cell:
------------------
G = cn.Graph.from_sif_tuples(
    [
        ("I1", 1, "N1"),  # I1 activates N1
        ("N1", 1, "M1"),  # N1 activates M1
        ("N1", 1, "M2"),  # N1 activaes M2
        ("I2", -1, "N2"),  # I2 inhibits N2
        ("N2", -1, "M2"),  # N2 inhibits M2
        ("N2", -1, "M1"),  # N2 inhibits M1
    ]
)
G.plot()
------------------


[0;31m---------------------------------------------------------------------------[0m
[0;31mAttributeError[0m                            Traceback (most recent call last)
Cell [0;32mIn[2], line 1[0m
[0;32m----> 1[0m G [38;5;241m=[39m [43mcn[49m[38;5;241;43m.[39;49m[43mGraph[49m[38;5;241;43m.[39;49m[43mfrom_sif_tuples[49m(
[1;32m      2[0m     [
[1;32m      3[0m         ([38;5;124m"[39m[38;5;124mI1[39m[38;5;124m"[39m, [38;5;241m1[39m, [38;5;124m"[39m[38;5;124mN1[39m[38;5;124m"[39m),  [38;5;66;03m# I1 activates N1[39;00m
[1;32m      4[0m         ([38;5;124m"[39m[38;5;124mN1[39m[38;5;124m"[39m, [38;5;241m1[39m, [38;5;124m"[39m[38;5;124mM1[39m[38;5;124m"[39m),  [38;5;66;03m# N1 activates M1[39;00m
[1;32m      5[0m         ([38;5;124m"[39m[38;5;124mN1[39m[38;5;124m"[39m, [38;5;241m1[39m, [38;5;124m"[39m[38;5;124mM2[39m[38;5;124m"[39m),  [38;5;66;03m# N1 activaes M2[39;00m
[1;32m      6[0m         ([38;5;124m"[39m[38;5;124mI2[39m[38;5;124m"[39m, [38;5;241m-[39m[38;5;241m1[39m, [38;5;124m"[39m[38;5;124mN2[39m[38;5;124m"[39m),  [38;5;66;03m# I2 inhibits N2[39;00m
[1;32m      7[0m         ([38;5;124m"[39m[38;5;124mN2[39m[38;5;124m"[39m, [38;5;241m-[39m[38;5;241m1[39m, [38;5;124m"[39m[38;5;124mM2[39m[38;5;124m"[39m),  [38;5;66;03m# N2 inhibits M2[39;00m
[1;32m      8[0m         ([38;5;124m"[39m[38;5;124mN2[39m[38;5;124m"[39m, [38;5;241m-[39m[38;5;241m1[39m, [38;5;124m"[39m[38;5;124mM1[39m[38;5;124m"[39m),  [38;5;66;03m# N2 inhibits M1[39;00m
[1;32m      9[0m     ]
[1;32m     10[0m )
[1;32m     11[0m G[38;5;241m.[39mplot()

[0;31mAttributeError[0m: type object 'Graph' has no attribute 'from_sif_tuples'

