Traceback (most recent call last):
  File "/home/runner/.cache/pypoetry/virtualenvs/corneto-lU1q7eKj-py3.11/lib/python3.11/site-packages/jupyter_cache/executors/utils.py", line 58, in single_nb_execution
    executenb(
  File "/home/runner/.cache/pypoetry/virtualenvs/corneto-lU1q7eKj-py3.11/lib/python3.11/site-packages/nbclient/client.py", line 1319, in execute
    return NotebookClient(nb=nb, resources=resources, km=km, **kwargs).execute()
           ^^^^^^^^^^^^^^^^^^^^^^^^^^^^^^^^^^^^^^^^^^^^^^^^^^^^^^^^^^^^^^^^^^^^^
  File "/home/runner/.cache/pypoetry/virtualenvs/corneto-lU1q7eKj-py3.11/lib/python3.11/site-packages/jupyter_core/utils/__init__.py", line 165, in wrapped
    return loop.run_until_complete(inner)
           ^^^^^^^^^^^^^^^^^^^^^^^^^^^^^^
  File "/opt/hostedtoolcache/Python/3.11.12/x64/lib/python3.11/asyncio/base_events.py", line 654, in run_until_complete
    return future.result()
           ^^^^^^^^^^^^^^^
  File "/home/runner/.cache/pypoetry/virtualenvs/corneto-lU1q7eKj-py3.11/lib/python3.11/site-packages/nbclient/client.py", line 709, in async_execute
    await self.async_execute_cell(
  File "/home/runner/.cache/pypoetry/virtualenvs/corneto-lU1q7eKj-py3.11/lib/python3.11/site-packages/nbclient/client.py", line 1062, in async_execute_cell
    await self._check_raise_for_error(cell, cell_index, exec_reply)
  File "/home/runner/.cache/pypoetry/virtualenvs/corneto-lU1q7eKj-py3.11/lib/python3.11/site-packages/nbclient/client.py", line 918, in _check_raise_for_error
    raise CellExecutionError.from_cell_and_msg(cell, exec_reply_content)
nbclient.exceptions.CellExecutionError: An error occurred while executing the following cell:
------------------
# Definition of the prior knowledge network
G1 = cn.Graph.from_sif_tuples(
    [
        ("EGF", 1, "AND1"),
        ("TNFa", 1, "AND1"),
        ("AND1", 1, "Ras"),
        ("EGF", 1, "Ras"),
        ("TNFa", 1, "Ras"),
    ]
)
G1.plot()
------------------


[0;31m---------------------------------------------------------------------------[0m
[0;31mAttributeError[0m                            Traceback (most recent call last)
Cell [0;32mIn[2], line 2[0m
[1;32m      1[0m [38;5;66;03m# Definition of the prior knowledge network[39;00m
[0;32m----> 2[0m G1 [38;5;241m=[39m [43mcn[49m[38;5;241;43m.[39;49m[43mGraph[49m[38;5;241;43m.[39;49m[43mfrom_sif_tuples[49m(
[1;32m      3[0m     [
[1;32m      4[0m         ([38;5;124m"[39m[38;5;124mEGF[39m[38;5;124m"[39m, [38;5;241m1[39m, [38;5;124m"[39m[38;5;124mAND1[39m[38;5;124m"[39m),
[1;32m      5[0m         ([38;5;124m"[39m[38;5;124mTNFa[39m[38;5;124m"[39m, [38;5;241m1[39m, [38;5;124m"[39m[38;5;124mAND1[39m[38;5;124m"[39m),
[1;32m      6[0m         ([38;5;124m"[39m[38;5;124mAND1[39m[38;5;124m"[39m, [38;5;241m1[39m, [38;5;124m"[39m[38;5;124mRas[39m[38;5;124m"[39m),
[1;32m      7[0m         ([38;5;124m"[39m[38;5;124mEGF[39m[38;5;124m"[39m, [38;5;241m1[39m, [38;5;124m"[39m[38;5;124mRas[39m[38;5;124m"[39m),
[1;32m      8[0m         ([38;5;124m"[39m[38;5;124mTNFa[39m[38;5;124m"[39m, [38;5;241m1[39m, [38;5;124m"[39m[38;5;124mRas[39m[38;5;124m"[39m),
[1;32m      9[0m     ]
[1;32m     10[0m )
[1;32m     11[0m G1[38;5;241m.[39mplot()

[0;31mAttributeError[0m: type object 'Graph' has no attribute 'from_sif_tuples'

